<?xml version="1.0"?>
<robot xmlns:xacro="http://www.ros.org/wiki/xacro">

  <xacro:macro name="rover_wheel" params="prefix parent *origin">
    <joint name="${prefix}wheel_link_joint" type="continuous">
      <parent link="${parent}"/>
      <child link="${prefix}wheel_link"/>
      <xacro:insert_block name="origin"/>
      <axis xyz="0 0 1"/>
      <limit lower="0" upper="0" effort="1000.0" velocity="100.0"/>
      <dynamics damping="0" friction="0.01"/>
    </joint>

    <link name="${prefix}wheel_link">
      <collision name="${prefix}wheel_collision">
        <origin xyz="0 0 0" rpy="0 0 0"/>
        <geometry>
          <mesh filename="file://$(find rover_description)/meshes/dae/Cylinder.005.dae" scale="0.5 0.5 0.5"/>
        </geometry>
        <surface>
          <friction>
            <ode>
              <mu>1.000</mu>
              <mu2>1.000</mu2>
            </ode>
          </friction>
        </surface>
      </collision>
      <inertial>
        <origin xyz="0 0 0" rpy="0 0 0"/>
        <mass value="10.0"/>
        <inertia ixx="1.78847" ixy="0.0" ixz="0.0"
                 iyy="1.02757" iyz="0.0" izz="1.02757"/>
      </inertial>
      <visual name="${prefix}wheel">
        <origin xyz="0 0 0" rpy="0 0 0"/>
        <geometry>
          <mesh filename="file://$(find rover_description)/meshes/dae/Cylinder.005.dae" scale="0.5 0.5 0.5"/>
        </geometry>
        <material name="${prefix}Material.001"/>
      </visual>
    </link>
    
    <transmission name="${prefix}wheel_joint_transmission">
      <type>transmission_interface/SimpleTransmission</type>
      <joint name="${prefix}wheel_link_joint">
        <hardwareInterface>hardware_interface/VelocityJointInterface</hardwareInterface>
      </joint>
      <actuator name="${prefix}wheel_joint_motor">
        <mechanicalReduction>1</mechanicalReduction>
      </actuator>
    </transmission>

    <gazebo reference="${prefix}wheel_link">
      <mu>5.000</mu>
      <mu2>5.000</mu2>
    </gazebo>

    <material name="${prefix}Material.001">
      <color rgba="0.00000 0.00000 0.00000 1.00000"/>
    </material>

  </xacro:macro>

</robot>
