<?xml version="1.0" ?>
<robot name="barrier">
    
	<!-- Poste fijo (cilindro rojo) -->
	<link name="cylinder">
        <inertial>
            <mass value="10"/>
            <origin xyz="0 0 0.2"/>
            <inertia ixx="0.1" ixy="0" ixz="0" iyy="0.1" iyz="0" izz="0.1"/>
        </inertial>
        <visual>
            <origin xyz="0 0 0.3"/>
            <geometry>
                <cylinder radius="0.2" length="0.3"/>
            </geometry>
            <material name="red">
                <color rgba="1 0 0 1"/>
            </material>
        </visual>
        <collision>
            <origin xyz="0 0 0.3"/>
            <geometry>
                <cylinder radius="0.2" length="0.3"/>
            </geometry>
        </collision>
    </link>

    <!-- Base giratoria de la barrera -->
	<link name="wrist_link">
        <inertial>
            <mass value="1"/>  
            <origin xyz="0 0 0"/>
            <inertia ixx="0.001" ixy="0" ixz="0" iyy="0.001" iyz="0" izz="0.001"/>
        </inertial>
        <visual>
            <origin xyz="0 0 0.0"/>
            <geometry>
                <cylinder radius="0.35" length="0.2"/>
            </geometry>
            <material name="red">
                <color rgba="1 0 0 1"/>
            </material>
        </visual>
        <collision>
            <origin xyz="0 0 0.0"/>
            <geometry>
                <cylinder radius="0.35" length="0.2"/>
            </geometry>
        </collision>
    </link>


    <!-- Brazo de la barrera móvil -->
    <link name="bar">
        <inertial>
            <mass value="5"/>  
            <origin xyz="0 0 0" rpy="0 0 0"/>
            <inertia ixx="0.05" ixy="0" ixz="0" iyy="0.05" iyz="0" izz="0.05"/>
        </inertial>
        <visual>
            <origin xyz="0 1.2 0"/>
            <geometry>
                <box size="0.1 2.22 0.2"/>
            </geometry>
            <material name="red">
                <color rgba="1 0 0 1"/>
            </material>
        </visual>
        <collision>
            <origin xyz="0 1.2 0"/>
            <geometry>
                <box size="0.1 2.22 0.2"/>
            </geometry>
        </collision>
    </link>

    <!-- Articulación de rotación en el extremo del brazo sobre el eje Z -->
    <joint name="rotation_joint" type="revolute">
        <parent link="cylinder"/>
        <child link="wrist_link"/>
        <origin xyz="0 0 0.5"/>
        <axis xyz="0 0 1"/>
        <limit lower="-1.57" upper="1.57"/>
        <dynamics damping="0.1"/>
    </joint>

    <!-- Fixed Joint Between Wrist and Arm -->
    <joint name="wrist_joint" type="fixed">
        <parent link="wrist_link"/>
        <child link="bar"/>
        <origin xyz="0 0.0 0.0"/>
    </joint>

</robot>
