<robot name="spydy_gonzalez" version="1.0">
  <joint name="left_center_wheel_link_joint" type="continuous">
    <limit lower="0" upper="0" effort="0.00000" velocity="0.00000"/>
    <origin rpy="-0.00000 1.57080 0.00000" xyz="-2.40000 0.00000 -0.80000"/>
    <parent link="base_link"/>
    <child link="left_center_wheel_link"/>
    <axis xyz="0.00000 0.00000 1.00000"/>
  </joint>
  <joint name="left_front_wheel_link_joint" type="continuous">
    <limit lower="0" upper="0" effort="0.00000" velocity="0.00000"/>
    <origin rpy="-0.00000 1.57080 0.00000" xyz="-2.40000 -2.60000 -0.80000"/>
    <parent link="base_link"/>
    <child link="left_front_wheel_link"/>
    <axis xyz="0.00000 0.00000 1.00000"/>
  </joint>
  <joint name="left_rear_wheel_link_joint" type="continuous">
    <limit lower="0" upper="0" effort="0.00000" velocity="0.00000"/>
    <origin rpy="-0.00000 1.57080 0.00000" xyz="-2.40000 2.60000 -0.80000"/>
    <parent link="base_link"/>
    <child link="left_rear_wheel_link"/>
    <axis xyz="0.00000 0.00000 1.00000"/>
  </joint>
  <joint name="right_center_wheel_link_joint" type="continuous">
    <limit lower="0" upper="0" effort="0.00000" velocity="0.00000"/>
    <origin rpy="-0.00000 1.57080 0.00000" xyz="2.40000 0.00000 -0.80000"/>
    <parent link="base_link"/>
    <child link="right_center_wheel_link"/>
    <axis xyz="0.00000 0.00000 1.00000"/>
  </joint>
  <joint name="right_front_wheel_link_joint" type="continuous">
    <limit lower="0" upper="0" effort="0.00000" velocity="0.00000"/>
    <origin rpy="-0.00000 1.57080 0.00000" xyz="2.40000 -2.60000 -0.80000"/>
    <parent link="base_link"/>
    <child link="right_front_wheel_link"/>
    <axis xyz="0.00000 0.00000 1.00000"/>
  </joint>
  <joint name="right_rear_wheel_link_joint" type="continuous">
    <limit lower="0" upper="0" effort="0.00000" velocity="0.00000"/>
    <origin rpy="-0.00000 1.57080 0.00000" xyz="2.40000 2.60000 -0.80000"/>
    <parent link="base_link"/>
    <child link="right_rear_wheel_link"/>
    <axis xyz="0.00000 0.00000 1.00000"/>
  </joint>
  <link name="base_link">
    <collision name="base_collision">
      <origin rpy="0.00000 0.00000 0.00000" xyz="0.00000 0.00000 0.00000"/>
      <geometry>
        <box size="4.00000 7.00000 3.00000"/>
      </geometry>
    </collision>
    <inertial>
      <inertia ixx="290.00000" ixy="0.00000" ixz="0.00000" iyy="125.00000" iyz="0.00000" izz="325.00000"/>
      <origin rpy="0.00000 0.00000 0.00000" xyz="0.00000 0.00000 0.00000"/>
      <mass value="60.00000"/>
    </inertial>
    <visual name="base">
      <origin rpy="0.00000 0.00000 0.00000" xyz="0.00000 0.00000 0.00000"/>
      <material name="phobos_indicator4"/>
      <geometry>
        <mesh filename="../meshes/dae/Cube.001.dae" scale="2.00000 3.50000 1.50000"/>
      </geometry>
    </visual>
  </link>
  <link name="left_center_wheel_link">
    <collision name="left_center_wheel_collision">
      <origin rpy="0.00000 0.00000 0.00000" xyz="-0.00000 0.00000 0.00000"/>
      <geometry>
        <mesh filename="../meshes/dae/Cylinder.005.dae" scale="1.00000 1.00000 1.00000"/>
      </geometry>
    </collision>
    <inertial>
      <inertia ixx="10.73082" ixy="0.00000" ixz="-0.00000" iyy="6.16541" iyz="0.00000" izz="6.16541"/>
      <origin rpy="0.00000 0.00000 0.00000" xyz="-0.00000 0.00000 0.00000"/>
      <mass value="15.00000"/>
    </inertial>
    <visual name="left_center_wheel">
      <origin rpy="0.00000 0.00000 0.00000" xyz="-0.00000 0.00000 0.00000"/>
      <material name="Material.001"/>
      <geometry>
        <mesh filename="../meshes/dae/Cylinder.005.dae" scale="1.00000 1.00000 1.00000"/>
      </geometry>
    </visual>
  </link>
  <link name="left_front_wheel_link">
    <collision name="left_front_wheel_collision">
      <origin rpy="0.00000 0.00000 0.00000" xyz="-0.00000 0.00000 0.00000"/>
      <geometry>
        <mesh filename="../meshes/dae/Cylinder.006.dae" scale="1.00000 1.00000 1.00000"/>
      </geometry>
    </collision>
    <inertial>
      <inertia ixx="10.73082" ixy="0.00000" ixz="-0.00000" iyy="6.16541" iyz="0.00000" izz="6.16541"/>
      <origin rpy="0.00000 0.00000 0.00000" xyz="-0.00000 0.00000 0.00000"/>
      <mass value="15.00000"/>
    </inertial>
    <visual name="left_front_wheel">
      <origin rpy="0.00000 0.00000 0.00000" xyz="-0.00000 0.00000 0.00000"/>
      <material name="Material.001"/>
      <geometry>
        <mesh filename="../meshes/dae/Cylinder.006.dae" scale="1.00000 1.00000 1.00000"/>
      </geometry>
    </visual>
  </link>
  <link name="left_rear_wheel_link">
    <collision name="left_rear_wheel_collision">
      <origin rpy="0.00000 0.00000 0.00000" xyz="-0.00000 -0.00000 0.00000"/>
      <geometry>
        <mesh filename="../meshes/dae/Cylinder.007.dae" scale="1.00000 1.00000 1.00000"/>
      </geometry>
    </collision>
    <inertial>
      <inertia ixx="10.73082" ixy="0.00000" ixz="-0.00000" iyy="6.16541" iyz="0.00000" izz="6.16541"/>
      <origin rpy="0.00000 0.00000 0.00000" xyz="-0.00000 -0.00000 0.00000"/>
      <mass value="15.00000"/>
    </inertial>
    <visual name="left_rear_wheel">
      <origin rpy="0.00000 0.00000 0.00000" xyz="-0.00000 -0.00000 0.00000"/>
      <material name="Material.001"/>
      <geometry>
        <mesh filename="../meshes/dae/Cylinder.007.dae" scale="1.00000 1.00000 1.00000"/>
      </geometry>
    </visual>
  </link>
  <link name="right_center_wheel_link">
    <collision name="right_center_wheel_collision">
      <origin rpy="0.00000 0.00000 0.00000" xyz="-0.00000 0.00000 -0.00000"/>
      <geometry>
        <mesh filename="../meshes/dae/Cylinder.002.dae" scale="1.00000 1.00000 1.00000"/>
      </geometry>
    </collision>
    <inertial>
      <inertia ixx="10.73082" ixy="0.00000" ixz="-0.00000" iyy="6.16541" iyz="0.00000" izz="6.16541"/>
      <origin rpy="0.00000 0.00000 0.00000" xyz="-0.00000 0.00000 -0.00000"/>
      <mass value="15.00000"/>
    </inertial>
    <visual name="right_center_wheel">
      <origin rpy="0.00000 0.00000 0.00000" xyz="-0.00000 0.00000 -0.00000"/>
      <material name="Material.001"/>
      <geometry>
        <mesh filename="../meshes/dae/Cylinder.002.dae" scale="1.00000 1.00000 1.00000"/>
      </geometry>
    </visual>
  </link>
  <link name="right_front_wheel_link">
    <collision name="right_front_wheel_collision">
      <origin rpy="0.00000 0.00000 0.00000" xyz="-0.00000 0.00000 -0.00000"/>
      <geometry>
        <mesh filename="../meshes/dae/Cylinder.004.dae" scale="1.00000 1.00000 1.00000"/>
      </geometry>
    </collision>
    <inertial>
      <inertia ixx="10.73082" ixy="0.00000" ixz="-0.00000" iyy="6.16541" iyz="0.00000" izz="6.16541"/>
      <origin rpy="0.00000 0.00000 0.00000" xyz="-0.00000 0.00000 -0.00000"/>
      <mass value="15.00000"/>
    </inertial>
    <visual name="right_front_wheel">
      <origin rpy="0.00000 0.00000 0.00000" xyz="-0.00000 0.00000 -0.00000"/>
      <material name="Material.001"/>
      <geometry>
        <mesh filename="../meshes/dae/Cylinder.004.dae" scale="1.00000 1.00000 1.00000"/>
      </geometry>
    </visual>
  </link>
  <link name="right_rear_wheel_link">
    <collision name="right_rear_wheel_collision">
      <origin rpy="0.00000 0.00000 0.00000" xyz="-0.00000 -0.00000 -0.00000"/>
      <geometry>
        <mesh filename="../meshes/dae/Cylinder.003.dae" scale="1.00000 1.00000 1.00000"/>
      </geometry>
    </collision>
    <inertial>
      <inertia ixx="10.73082" ixy="0.00000" ixz="-0.00000" iyy="6.16541" iyz="0.00000" izz="6.16541"/>
      <origin rpy="0.00000 0.00000 0.00000" xyz="-0.00000 -0.00000 -0.00000"/>
      <mass value="15.00000"/>
    </inertial>
    <visual name="right_rear_wheel">
      <origin rpy="0.00000 0.00000 0.00000" xyz="-0.00000 -0.00000 -0.00000"/>
      <material name="Material.001"/>
      <geometry>
        <mesh filename="../meshes/dae/Cylinder.003.dae" scale="1.00000 1.00000 1.00000"/>
      </geometry>
    </visual>
  </link>
  <material name="Material.001">
    <color rgba="0.00000 0.00000 0.00000 1.00000"/>
  </material>
  <material name="phobos_indicator4">
    <color rgba="1.00000 0.00000 1.00000 1.00000"/>
  </material>
</robot>